Workbook
Name ChestValueDeadwoodCanyon: 'Chest Rates'!$B$65:$S$71
Name ChestDataCavesofFear: 'Chest Rates'!$B$29:$G$39
Name ChestValueCavesofFear: 'Chest Rates'!$B$74:$S$80
Name ClearsPerEnchantmentRockyPlateau: 'Chest Rates'!$C$131:$S$151
Name ChestValueMushroomForest: 'Chest Rates'!$B$83:$S$89
Name ChestValueIcyRidge: 'Chest Rates'!$B$110:$S$116
Name ClearsPerEnchantmentCavesofFear: 'Chest Rates'!$C$181:$S$201
Name ChestValueHauntedHalls: 'Chest Rates'!$B$92:$S$98
Name ChestDataHauntedHalls: 'Chest Rates'!$I$3:$N$13
Name ClearsPerEnchantmentTemple: 'Chest Rates'!$C$306:$S$326
Name ClearsPerEnchantmentMushroomForest: 'Chest Rates'!$C$206:$S$226
Name ChestDataIcyRidge: 'Chest Rates'!$I$29:$N$39
Name ChestDataTemple: 'Chest Rates'!$I$42:$N$52
Name ClearsPerEnchantmentHauntedHalls: 'Chest Rates'!$C$231:$S$251
Name ChestValueBoilingMine: 'Chest Rates'!$B$101:$S$107
Name ChestDataMushroomForest: 'Chest Rates'!$B$42:$G$52
Name ClearsPerEnchantmentIcyRidge: 'Chest Rates'!$C$281:$S$301
Name ClearsPerEnchantmentBoilingMine: 'Chest Rates'!$C$256:$S$276
Name ChestDataBoilingMine: 'Chest Rates'!$I$16:$N$26
Name ChestValueRockyPlateau: 'Chest Rates'!$B$56:$S$62
Name ChestDataDeadwoodCanyon: 'Chest Rates'!$B$16:$G$26
Name ClearsPerEnchantmentDeadwoodCanyon: 'Chest Rates'!$C$156:$S$176
Name ChestValueTemple: 'Chest Rates'!$B$119:$S$125
Name ChestDataRockyPlateau: 'Chest Rates'!$B$3:$G$13

Sheet Enchant Stats
D3: Common | F3: Uncommon | H3: Rare | J3: Heroic | L3: Epic | N3: Legendary | P3: Transcendent
B4: · Humble · | D4: 122880 | F4: 1024 | H4: 64
B5: o Common o | D5: 109600 | F5: 1024 | H5: 61 | J5: 11
B6: 8 Giant 8 | D6: 15800 | F6: 2180 | H6: 158 | J6: 32
B7: Ω Omega Ω | D7: 1000 | F7: 530 | H7: 240 | J7: 27 | L7: 3
B8: Δ Delta Δ | D8: 200 | F8: 26 | H8: 90 | J8: 69 | L8: 14 | N8: 1
B9: Skullnata | D9: 400 | F9: 50 | H9: 240 | J9: 101 | L9: 8 | N9: 1
B12: Enchant Rank | E12: 1 | F12: 2 | G12: 3 | H12: 4 | I12: 5 | J12: 6 | K12: 7 | L12: 8 | M12: 9 | N12: 10 | O12: 11 | P12: 12 | Q12: 13 | R12: 14 | S12: 15 | T12: 16 | U12: 17 | V12: 18 | W12: 19 | X12: 20 | Y12: 21
B13: Total Value | E13: 1 | F13: 4 | G13: 7 | H13: 19 | I13: 31 | J13: 43 | K13: 100 | L13: 157 | M13: 214 | N13: 271 | O13: 571 | P13: 871 | Q13: 1171 | R13: 1471 | S13: 1771 | T13: 3484 | U13: 5197 | V13: 6910 | W13: 8623 | X13: 10336 | Y13: 12049
B14: Req. For Rank-up | E14: 3 | F14: 3 | G14: 12 | H14: 12 | I14: 12 | J14: 57 | K14: 57 | L14: 57 | M14: 57 | N14: 300 | O14: 300 | P14: 300 | Q14: 300 | R14: 300 | S14: 1713 | T14: 1713 | U14: 1713 | V14: 1713 | W14: 1713 | X14: 1713 | Y14: 10452
B15: 3x Equivalency | E15: +1 | F15: +1 | G15: +2 | H15: +2 | I15: +2 | J15: +4 | K15: +4 | L15: +4 | M15: +4 | N15: +7 | O15: +7 | P15: +7 | Q15: +7 | R15: +7 | S15: +11 | T15: +11 | U15: +11 | V15: +11 | W15: +11 | X15: +11 | Y15: +16
D18: Common | E18: Uncommon | F18: Rare | H18: Heroic | K18: Epic | O18: Legendary | T18: Transcendent
B19: · Humble · | D19: =IF(1-SUM(E19:T19) = 0, , 1-SUM(E19:T19)) -> 0.99114583 | E19: =IF(F4/$D4 = 0, , F4/$D4) -> 0.0083333333 | F19: =IF(H4/$D4 = 0, , H4/$D4) -> 0.00052083333 | H19: =IF(J4/$D4 = 0, , J4/$D4) | K19: =IF(L4/$D4 = 0, , L4/$D4) | O19: =IF(N4/$D4 = 0, , N4/$D4) | T19: =IF(P4/$D4 = 0, , P4/$D4)
B20: o Common o | D20: =IF(1-SUM(E20:T20) = 0, , 1-SUM(E20:T20)) -> 0.99 | E20: =IF(F5/$D5 = 0, , F5/$D5) -> 0.0093430657 | F20: =IF(H5/$D5 = 0, , H5/$D5) -> 0.00055656934 | H20: =IF(J5/$D5 = 0, , J5/$D5) -> 0.00010036496 | K20: =IF(L5/$D5 = 0, , L5/$D5) | O20: =IF(N5/$D5 = 0, , N5/$D5) | T20: =IF(P5/$D5 = 0, , P5/$D5)
B21: 8 Giant 8 | D21: =IF(1-SUM(E21:T21) = 0, , 1-SUM(E21:T21)) -> 0.85 | E21: =IF(F6/$D6 = 0, , F6/$D6) -> 0.13797468 | F21: =IF(H6/$D6 = 0, , H6/$D6) -> 0.01 | H21: =IF(J6/$D6 = 0, , J6/$D6) -> 0.0020253165 | K21: =IF(L6/$D6 = 0, , L6/$D6) | O21: =IF(N6/$D6 = 0, , N6/$D6) | T21: =IF(P6/$D6 = 0, , P6/$D6)
B22: Ω Omega Ω | D22: =IF(1-SUM(E22:T22) = 0, , 1-SUM(E22:T22)) -> 0.2 | E22: =IF(F7/$D7 = 0, , F7/$D7) -> 0.53 | F22: =IF(H7/$D7 = 0, , H7/$D7) -> 0.24 | H22: =IF(J7/$D7 = 0, , J7/$D7) -> 0.027 | K22: =IF(L7/$D7 = 0, , L7/$D7) -> 0.003 | O22: =IF(N7/$D7 = 0, , N7/$D7) | T22: =IF(P7/$D7 = 0, , P7/$D7)
B23: Δ Delta Δ | D23: =IF(1-SUM(E23:T23) = 0, , 1-SUM(E23:T23)) | E23: =IF(F8/$D8 = 0, , F8/$D8) -> 0.13 | F23: =IF(H8/$D8 = 0, , H8/$D8) -> 0.45 | H23: =IF(J8/$D8 = 0, , J8/$D8) -> 0.345 | K23: =IF(L8/$D8 = 0, , L8/$D8) -> 0.07 | O23: =IF(N8/$D8 = 0, , N8/$D8) -> 0.005 | T23: =IF(P8/$D8 = 0, , P8/$D8)
B24: Skullnata | D24: =IF(1-SUM(E24:T24) = 0, , 1-SUM(E24:T24)) | E24: =IF(F9/$D9 = 0, , F9/$D9) -> 0.125 | F24: =IF(H9/$D9 = 0, , H9/$D9) -> 0.6 | H24: =IF(J9/$D9 = 0, , J9/$D9) -> 0.2525 | K24: =IF(L9/$D9 = 0, , L9/$D9) -> 0.02 | O24: =IF(N9/$D9 = 0, , N9/$D9) -> 0.0025 | T24: =IF(U9/$D9 = 0, , U9/$D9)
B27: Enchant Rank | D27: 0 | E27: 1 | F27: 2 | G27: 3 | H27: 4 | I27: 5 | J27: 6 | K27: 7 | L27: 8 | M27: 9 | N27: 10 | O27: 11 | P27: 12 | Q27: 13 | R27: 14 | S27: 15 | T27: 16 | U27: 17 | V27: 18 | W27: 19 | X27: 20 | Y27: 21
B28: · Humble · | D28: =IF(D19/1 = 0, ,D19/1) -> 0.99114583 | E28: =IF(E19/1 = 0, ,E19/1) -> 0.0083333333 | F28: =IF($F19-($F19*(0.1/(3-2))) = 0, , $F19-($F19*(0.1/(3-2)))) -> 0.00046875 | G28: =IF($F19*(0.1/(3-2)) = 0, , $F19*(0.1/(3-2))) -> 5.2083333e-05 | H28: =IF(($H19-($H19*(0.1/(6-4))))/2 = 0, , ($H19-($H19*(0.1/(6-4))))/2) | I28: =IF(($H19-($H19*(0.1/(6-4))))/2 = 0, , ($H19-($H19*(0.1/(6-4))))/2) | J28: =IF($H19*(0.1/(6-4)) = 0, , $H19*(0.1/(6-4))) | K28: =IF(($K19-($K19*(0.1/(10-7))))/3 = 0, , ($K19-($K19*(0.1/(10-7))))/3) | L28: =IF(($K19-($K19*(0.1/(10-7))))/3 = 0, , ($K19-($K19*(0.1/(10-7))))/3) | M28: =IF(($K19-($K19*(0.1/(10-7))))/3 = 0, , ($K19-($K19*(0.1/(10-7))))/3) | N28: =IF($K19*(0.1/(10-7)) = 0, , $K19*(0.1/(10-7))) | O28: =IF(($O19-($O19*(0.1/(6-4))))/4 = 0, , ($O19-($O19*(0.1/(6-4))))/4) | P28: =IF(($O19-($O19*(0.1/(6-4))))/4 = 0, , ($O19-($O19*(0.1/(6-4))))/4) | Q28: =IF(($O19-($O19*(0.1/(6-4))))/4 = 0, , ($O19-($O19*(0.1/(6-4))))/4) | R28: =IF(($O19-($O19*(0.1/(6-4))))/4 = 0, , ($O19-($O19*(0.1/(6-4))))/4) | S28: =IF(O19*(0.1/(15-11)) = 0, , O19*(0.1/(15-11))) | T28: =IF(($T19-($T19*(0.1/(6-4))))/5 = 0, , ($T19-($T19*(0.1/(6-4))))/5) | U28: =IF(($T19-($T19*(0.1/(6-4))))/5 = 0, , ($T19-($T19*(0.1/(6-4))))/5) | V28: =IF(($T19-($T19*(0.1/(6-4))))/5 = 0, , ($T19-($T19*(0.1/(6-4))))/5) | W28: =IF(($T19-($T19*(0.1/(6-4))))/5 = 0, , ($T19-($T19*(0.1/(6-4))))/5) | X28: =IF(($T19-($T19*(0.1/(6-4))))/5 = 0, , ($T19-($T19*(0.1/(6-4))))/5) | Y28: =IF(T19*(0.1/(21-16)) = 0, , T19*(0.1/(21-16)))
B29: o Common o | D29: =IF(D20/1 = 0, ,D20/1) -> 0.99 | E29: =IF(E20/1 = 0, ,E20/1) -> 0.0093430657 | F29: =IF($F20-($F20*(0.1/(3-2))) = 0, , $F20-($F20*(0.1/(3-2)))) -> 0.00050091241 | G29: =IF($F20*(0.1/(3-2)) = 0, , $F20*(0.1/(3-2))) -> 5.5656934e-05 | H29: =IF(($H20-($H20*(0.1/(6-4))))/2 = 0, , ($H20-($H20*(0.1/(6-4))))/2) -> 4.7673358e-05 | I29: =IF(($H20-($H20*(0.1/(6-4))))/2 = 0, , ($H20-($H20*(0.1/(6-4))))/2) -> 4.7673358e-05 | J29: =IF($H20*(0.1/(6-4)) = 0, , $H20*(0.1/(6-4))) -> 5.0182482e-06 | K29: =IF(($K20-($K20*(0.1/(10-7))))/3 = 0, , ($K20-($K20*(0.1/(10-7))))/3) | L29: =IF(($K20-($K20*(0.1/(10-7))))/3 = 0, , ($K20-($K20*(0.1/(10-7))))/3) | M29: =IF(($K20-($K20*(0.1/(10-7))))/3 = 0, , ($K20-($K20*(0.1/(10-7))))/3) | N29: =IF($K20*(0.1/(10-7)) = 0, , $K20*(0.1/(10-7))) | O29: =IF(($O20-($O20*(0.1/(6-4))))/4 = 0, , ($O20-($O20*(0.1/(6-4))))/4) | P29: =IF(($O20-($O20*(0.1/(6-4))))/4 = 0, , ($O20-($O20*(0.1/(6-4))))/4) | Q29: =IF(($O20-($O20*(0.1/(6-4))))/4 = 0, , ($O20-($O20*(0.1/(6-4))))/4) | R29: =IF(($O20-($O20*(0.1/(6-4))))/4 = 0, , ($O20-($O20*(0.1/(6-4))))/4) | S29: =IF(O20*(0.1/(15-11)) = 0, , O20*(0.1/(15-11))) | T29: =IF(($T20-($T20*(0.1/(6-4))))/5 = 0, , ($T20-($T20*(0.1/(6-4))))/5) | U29: =IF(($T20-($T20*(0.1/(6-4))))/5 = 0, , ($T20-($T20*(0.1/(6-4))))/5) | V29: =IF(($T20-($T20*(0.1/(6-4))))/5 = 0, , ($T20-($T20*(0.1/(6-4))))/5) | W29: =IF(($T20-($T20*(0.1/(6-4))))/5 = 0, , ($T20-($T20*(0.1/(6-4))))/5) | X29: =IF(($T20-($T20*(0.1/(6-4))))/5 = 0, , ($T20-($T20*(0.1/(6-4))))/5) | Y29: =IF(T20*(0.1/(21-16)) = 0, , T20*(0.1/(21-16)))
B30: 8 Giant 8 | D30: =IF(D21/1 = 0, ,D21/1) -> 0.85 | E30: =IF(E21/1 = 0, ,E21/1) -> 0.13797468 | F30: =IF($F21-($F21*(0.1/(3-2))) = 0, , $F21-($F21*(0.1/(3-2)))) -> 0.009 | G30: =IF($F21*(0.1/(3-2)) = 0, , $F21*(0.1/(3-2))) -> 0.001 | H30: =IF(($H21-($H21*(0.1/(6-4))))/2 = 0, , ($H21-($H21*(0.1/(6-4))))/2) -> 0.00096202532 | I30: =IF(($H21-($H21*(0.1/(6-4))))/2 = 0, , ($H21-($H21*(0.1/(6-4))))/2) -> 0.00096202532 | J30: =IF($H21*(0.1/(6-4)) = 0, , $H21*(0.1/(6-4))) -> 0.00010126582 | K30: =IF(($K21-($K21*(0.1/(10-7))))/3 = 0, , ($K21-($K21*(0.1/(10-7))))/3) | L30: =IF(($K21-($K21*(0.1/(10-7))))/3 = 0, , ($K21-($K21*(0.1/(10-7))))/3) | M30: =IF(($K21-($K21*(0.1/(10-7))))/3 = 0, , ($K21-($K21*(0.1/(10-7))))/3) | N30: =IF($K21*(0.1/(10-7)) = 0, , $K21*(0.1/(10-7))) | O30: =IF(($O21-($O21*(0.1/(6-4))))/4 = 0, , ($O21-($O21*(0.1/(6-4))))/4) | P30: =IF(($O21-($O21*(0.1/(6-4))))/4 = 0, , ($O21-($O21*(0.1/(6-4))))/4) | Q30: =IF(($O21-($O21*(0.1/(6-4))))/4 = 0, , ($O21-($O21*(0.1/(6-4))))/4) | R30: =IF(($O21-($O21*(0.1/(6-4))))/4 = 0, , ($O21-($O21*(0.1/(6-4))))/4) | S30: =IF(O21*(0.1/(15-11)) = 0, , O21*(0.1/(15-11))) | T30: =IF(($T21-($T21*(0.1/(6-4))))/5 = 0, , ($T21-($T21*(0.1/(6-4))))/5) | U30: =IF(($T21-($T21*(0.1/(6-4))))/5 = 0, , ($T21-($T21*(0.1/(6-4))))/5) | V30: =IF(($T21-($T21*(0.1/(6-4))))/5 = 0, , ($T21-($T21*(0.1/(6-4))))/5) | W30: =IF(($T21-($T21*(0.1/(6-4))))/5 = 0, , ($T21-($T21*(0.1/(6-4))))/5) | X30: =IF(($T21-($T21*(0.1/(6-4))))/5 = 0, , ($T21-($T21*(0.1/(6-4))))/5) | Y30: =IF(T21*(0.1/(21-16)) = 0, , T21*(0.1/(21-16)))
B31: Ω Omega Ω | D31: =IF(D22/1 = 0, ,D22/1) -> 0.2 | E31: =IF(E22/1 = 0, ,E22/1) -> 0.53 | F31: =IF($F22-($F22*(0.1/(3-2))) = 0, , $F22-($F22*(0.1/(3-2)))) -> 0.216 | G31: =IF($F22*(0.1/(3-2)) = 0, , $F22*(0.1/(3-2))) -> 0.024 | H31: =IF(($H22-($H22*(0.1/(6-4))))/2 = 0, , ($H22-($H22*(0.1/(6-4))))/2) -> 0.012825 | I31: =IF(($H22-($H22*(0.1/(6-4))))/2 = 0, , ($H22-($H22*(0.1/(6-4))))/2) -> 0.012825 | J31: =IF($H22*(0.1/(6-4)) = 0, , $H22*(0.1/(6-4))) -> 0.00135 | K31: =IF(($K22-($K22*(0.1/(10-7))))/3 = 0, , ($K22-($K22*(0.1/(10-7))))/3) -> 0.00096666667 | L31: =IF(($K22-($K22*(0.1/(10-7))))/3 = 0, , ($K22-($K22*(0.1/(10-7))))/3) -> 0.00096666667 | M31: =IF(($K22-($K22*(0.1/(10-7))))/3 = 0, , ($K22-($K22*(0.1/(10-7))))/3) -> 0.00096666667 | N31: =IF($K22*(0.1/(10-7)) = 0, , $K22*(0.1/(10-7))) -> 0.0001 | O31: =IF(($O22-($O22*(0.1/(6-4))))/4 = 0, , ($O22-($O22*(0.1/(6-4))))/4) | P31: =IF(($O22-($O22*(0.1/(6-4))))/4 = 0, , ($O22-($O22*(0.1/(6-4))))/4) | Q31: =IF(($O22-($O22*(0.1/(6-4))))/4 = 0, , ($O22-($O22*(0.1/(6-4))))/4) | R31: =IF(($O22-($O22*(0.1/(6-4))))/4 = 0, , ($O22-($O22*(0.1/(6-4))))/4) | S31: =IF(O22*(0.1/(15-11)) = 0, , O22*(0.1/(15-11))) | T31: =IF(($T22-($T22*(0.1/(6-4))))/5 = 0, , ($T22-($T22*(0.1/(6-4))))/5) | U31: =IF(($T22-($T22*(0.1/(6-4))))/5 = 0, , ($T22-($T22*(0.1/(6-4))))/5) | V31: =IF(($T22-($T22*(0.1/(6-4))))/5 = 0, , ($T22-($T22*(0.1/(6-4))))/5) | W31: =IF(($T22-($T22*(0.1/(6-4))))/5 = 0, , ($T22-($T22*(0.1/(6-4))))/5) | X31: =IF(($T22-($T22*(0.1/(6-4))))/5 = 0, , ($T22-($T22*(0.1/(6-4))))/5) | Y31: =IF(T22*(0.1/(21-16)) = 0, , T22*(0.1/(21-16)))
B32: Δ Delta Δ | D32: =IF(D23/1 = 0, ,D23/1) | E32: =IF(E23/1 = 0, ,E23/1) -> 0.13 | F32: =IF($F23-($F23*(0.1/(3-2))) = 0, , $F23-($F23*(0.1/(3-2)))) -> 0.405 | G32: =IF($F23*(0.1/(3-2)) = 0, , $F23*(0.1/(3-2))) -> 0.045 | H32: =IF(($H23-($H23*(0.1/(6-4))))/2 = 0, , ($H23-($H23*(0.1/(6-4))))/2) -> 0.163875 | I32: =IF(($H23-($H23*(0.1/(6-4))))/2 = 0, , ($H23-($H23*(0.1/(6-4))))/2) -> 0.163875 | J32: =IF($H23*(0.1/(6-4)) = 0, , $H23*(0.1/(6-4))) -> 0.01725 | K32: =IF(($K23-($K23*(0.1/(10-7))))/3 = 0, , ($K23-($K23*(0.1/(10-7))))/3) -> 0.022555556 | L32: =IF(($K23-($K23*(0.1/(10-7))))/3 = 0, , ($K23-($K23*(0.1/(10-7))))/3) -> 0.022555556 | M32: =IF(($K23-($K23*(0.1/(10-7))))/3 = 0, , ($K23-($K23*(0.1/(10-7))))/3) -> 0.022555556 | N32: =IF($K23*(0.1/(10-7)) = 0, , $K23*(0.1/(10-7))) -> 0.0023333333 | O32: =IF(($O23-($O23*(0.1/(6-4))))/4 = 0, , ($O23-($O23*(0.1/(6-4))))/4) -> 0.0011875 | P32: =IF(($O23-($O23*(0.1/(6-4))))/4 = 0, , ($O23-($O23*(0.1/(6-4))))/4) -> 0.0011875 | Q32: =IF(($O23-($O23*(0.1/(6-4))))/4 = 0, , ($O23-($O23*(0.1/(6-4))))/4) -> 0.0011875 | R32: =IF(($O23-($O23*(0.1/(6-4))))/4 = 0, , ($O23-($O23*(0.1/(6-4))))/4) -> 0.0011875 | S32: =IF(O23*(0.1/(15-11)) = 0, , O23*(0.1/(15-11))) -> 0.000125 | T32: =IF(($T23-($T23*(0.1/(6-4))))/5 = 0, , ($T23-($T23*(0.1/(6-4))))/5) | U32: =IF(($T23-($T23*(0.1/(6-4))))/5 = 0, , ($T23-($T23*(0.1/(6-4))))/5) | V32: =IF(($T23-($T23*(0.1/(6-4))))/5 = 0, , ($T23-($T23*(0.1/(6-4))))/5) | W32: =IF(($T23-($T23*(0.1/(6-4))))/5 = 0, , ($T23-($T23*(0.1/(6-4))))/5) | X32: =IF(($T23-($T23*(0.1/(6-4))))/5 = 0, , ($T23-($T23*(0.1/(6-4))))/5) | Y32: =IF(T23*(0.1/(21-16)) = 0, , T23*(0.1/(21-16)))
B33: Skullnata | D33: =IF(D24/1 = 0, ,D24/1) | E33: =IF(E24/1 = 0, ,E24/1) -> 0.125 | F33: =IF($F24-($F24*(0.1/(3-2))) = 0, , $F24-($F24*(0.1/(3-2)))) -> 0.54 | G33: =IF($F24*(0.1/(3-2)) = 0, , $F24*(0.1/(3-2))) -> 0.06 | H33: =IF(($H24-($H24*(0.1/(6-4))))/2 = 0, , ($H24-($H24*(0.1/(6-4))))/2) -> 0.1199375 | I33: =IF(($H24-($H24*(0.1/(6-4))))/2 = 0, , ($H24-($H24*(0.1/(6-4))))/2) -> 0.1199375 | J33: =IF($H24*(0.1/(6-4)) = 0, , $H24*(0.1/(6-4))) -> 0.012625 | K33: =IF(($K24-($K24*(0.1/(10-7))))/3 = 0, , ($K24-($K24*(0.1/(10-7))))/3) -> 0.0064444444 | L33: =IF(($K24-($K24*(0.1/(10-7))))/3 = 0, , ($K24-($K24*(0.1/(10-7))))/3) -> 0.0064444444 | M33: =IF(($K24-($K24*(0.1/(10-7))))/3 = 0, , ($K24-($K24*(0.1/(10-7))))/3) -> 0.0064444444 | N33: =IF($K24*(0.1/(10-7)) = 0, , $K24*(0.1/(10-7))) -> 0.00066666667 | O33: =IF(($O24-($O24*(0.1/(6-4))))/4 = 0, , ($O24-($O24*(0.1/(6-4))))/4) -> 0.00059375 | P33: =IF(($O24-($O24*(0.1/(6-4))))/4 = 0, , ($O24-($O24*(0.1/(6-4))))/4) -> 0.00059375 | Q33: =IF(($O24-($O24*(0.1/(6-4))))/4 = 0, , ($O24-($O24*(0.1/(6-4))))/4) -> 0.00059375 | R33: =IF(($O24-($O24*(0.1/(6-4))))/4 = 0, , ($O24-($O24*(0.1/(6-4))))/4) -> 0.00059375 | S33: =IF(O24*(0.1/(15-11)) = 0, , O24*(0.1/(15-11))) -> 6.25e-05 | T33: =IF(($T24-($T24*(0.1/(6-4))))/5 = 0, , ($T24-($T24*(0.1/(6-4))))/5) | U33: =IF(($T24-($T24*(0.1/(6-4))))/5 = 0, , ($T24-($T24*(0.1/(6-4))))/5) | V33: =IF(($T24-($T24*(0.1/(6-4))))/5 = 0, , ($T24-($T24*(0.1/(6-4))))/5) | W33: =IF(($T24-($T24*(0.1/(6-4))))/5 = 0, , ($T24-($T24*(0.1/(6-4))))/5) | X33: =IF(($T24-($T24*(0.1/(6-4))))/5 = 0, , ($T24-($T24*(0.1/(6-4))))/5) | Y33: =IF(T24*(0.1/(21-16)) = 0, , T24*(0.1/(21-16)))
B35: Chest Enchant Value Averages | D35: Total Value
E36: 1 | F36: 2 | G36: 3 | H36: 4 | I36: 5 | J36: 6 | K36: 7 | L36: 8 | M36: 9 | N36: 10 | O36: 11 | P36: 12 | Q36: 13 | R36: 14 | S36: 15 | T36: 16 | U36: 17 | V36: 18 | W36: 19 | X36: 20 | Y36: 21
B37: · Humble · | D37: =sum(E37:Y37) -> 0.010572917 | E37: =IF(E$13*E28 = 0, ,E$13*E28) -> 0.0083333333 | F37: =IF(F$13*F28 = 0, ,F$13*F28) -> 0.001875 | G37: =IF(G$13*G28 = 0, ,G$13*G28) -> 0.00036458333 | H37: =IF(H$13*H28 = 0, ,H$13*H28) | I37: =IF(I$13*I28 = 0, ,I$13*I28) | J37: =IF(J$13*J28 = 0, ,J$13*J28) | K37: =IF(K$13*K28 = 0, ,K$13*K28) | L37: =IF(L$13*L28 = 0, ,L$13*L28) | ... Y37: =IF(Y$13*Y28 = 0, ,Y$13*Y28)
B38: o Common o | D38: =sum(E38:Y38) -> 0.014335766 | E38: =IF(E$13*E29 = 0, ,E$13*E29) -> 0.0093430657 | F38: =IF(F$13*F29 = 0, ,F$13*F29) -> 0.0020036496 | G38: =IF(G$13*G29 = 0, ,G$13*G29) -> 0.00038959854 | H38: =IF(H$13*H29 = 0, ,H$13*H29) -> 0.0009057938 | I38: =IF(I$13*I29 = 0, ,I$13*I29) -> 0.0014778741 | J38: =IF(J$13*J29 = 0, ,J$13*J29) -> 0.00021578467 | K38: =IF(K$13*K29 = 0, ,K$13*K29) | L38: =IF(L$13*L29 = 0, ,L$13*L29) | ... Y38: =IF(Y$13*Y29 = 0, ,Y$13*Y29)
B39: 8 Giant 8 | D39: =sum(E39:Y39) -> 0.23343038 | E39: =IF(E$13*E30 = 0, ,E$13*E30) -> 0.13797468 | F39: =IF(F$13*F30 = 0, ,F$13*F30) -> 0.036 | G39: =IF(G$13*G30 = 0, ,G$13*G30) -> 0.007 | H39: =IF(H$13*H30 = 0, ,H$13*H30) -> 0.018278481 | I39: =IF(I$13*I30 = 0, ,I$13*I30) -> 0.029822785 | J39: =IF(J$13*J30 = 0, ,J$13*J30) -> 0.0043544304 | K39: =IF(K$13*K30 = 0, ,K$13*K30) | L39: =IF(L$13*L30 = 0, ,L$13*L30) | ... Y39: =IF(Y$13*Y30 = 0, ,Y$13*Y30)
B40: Ω Omega Ω | D40: =sum(E40:Y40) -> 2.7437 | E40: =IF(E$13*E31 = 0, ,E$13*E31) -> 0.53 | F40: =IF(F$13*F31 = 0, ,F$13*F31) -> 0.864 | G40: =IF(G$13*G31 = 0, ,G$13*G31) -> 0.168 | H40: =IF(H$13*H31 = 0, ,H$13*H31) -> 0.243675 | I40: =IF(I$13*I31 = 0, ,I$13*I31) -> 0.397575 | J40: =IF(J$13*J31 = 0, ,J$13*J31) -> 0.05805 | K40: =IF(K$13*K31 = 0, ,K$13*K31) -> 0.096666667 | L40: =IF(L$13*L31 = 0, ,L$13*L31) -> 0.15176667 | ... Y40: =IF(Y$13*Y31 = 0, ,Y$13*Y31)
B41: Δ Delta Δ | D41: =sum(E41:Y41) -> 27.327625 | E41: =IF(E$13*E32 = 0, ,E$13*E32) -> 0.13 | F41: =IF(F$13*F32 = 0, ,F$13*F32) -> 1.62 | G41: =IF(G$13*G32 = 0, ,G$13*G32) -> 0.315 | H41: =IF(H$13*H32 = 0, ,H$13*H32) -> 3.113625 | I41: =IF(I$13*I32 = 0, ,I$13*I32) -> 5.080125 | J41: =IF(J$13*J32 = 0, ,J$13*J32) -> 0.74175 | K41: =IF(K$13*K32 = 0, ,K$13*K32) -> 2.2555556 | L41: =IF(L$13*L32 = 0, ,L$13*L32) -> 3.5412222 | ... Y41: =IF(Y$13*Y32 = 0, ,Y$13*Y32)
B42: Skullnata | D42: =sum(E42:Y42) -> 14.996313 | E42: =IF(E$13*E33 = 0, ,E$13*E33) -> 0.125 | F42: =IF(F$13*F33 = 0, ,F$13*F33) -> 2.16 | G42: =IF(G$13*G33 = 0, ,G$13*G33) -> 0.42 | H42: =IF(H$13*H33 = 0, ,H$13*H33) -> 2.2788125 | I42: =IF(I$13*I33 = 0, ,I$13*I33) -> 3.7180625 | J42: =IF(J$13*J33 = 0, ,J$13*J33) -> 0.542875 | K42: =IF(K$13*K33 = 0, ,K$13*K33) -> 0.64444444 | L42: =IF(L$13*L33 = 0, ,L$13*L33) -> 1.0117778 | ... Y42: =IF(Y$13*Y33 = 0, ,Y$13*Y33)

Sheet Chest Rates
B3: Rocky Plateau Chest Data | D3: White | E3: Cyan | F3: Yellow | G3: Green | I3: Haunted Halls Chest Data | K3: White | L3: Cyan | M3: Yellow | N3: Green
B4: o Common o | D4: 0.74 | E4: 0.2 | F4: =I57 -> 0.0625 | G4: 0.97925 | I4: o Common o | K4: 0.8 | L4: 0.865 | M4: 0.68 | N4: 0.97925
B5: 8 Giant 8 | D5: 0.22 | E5: 0.7 | F5: =I58 -> 0.7 | I5: 8 Giant 8 | K5: 0.17 | L5: 0.1 | M5: 0.25
B6: Ω Omega Ω | D6: 0.03 | E6: 0.075 | F6: =I59 -> 0.205 | G6: 0.02 | I6: Ω Omega Ω | K6: 0.025 | L6: 0.03 | M6: 0.06 | N6: 0.02
B7: Δ Delta Δ | D7: 0.01 | E7: 0.025 | F7: =I60 -> 0.0325 | G7: 0.0005 | I7: Δ Delta Δ | K7: 0.005 | L7: 0.005 | M7: 0.01 | N7: 0.0005
B8: Emerald Egg | G8: 0.00025 | I8: Emerald Egg | N8: 0.00025
B9: Common mod | E9: -0.0275 | F9: -0.0125 | G9: -0.02625 | I9: Common mod | L9: -0.01 | M9: -0.015 | N9: -0.024
B10: Giant mod | E10: 0 | F10: -0.0325 | I10: Giant mod | L10: 0 | M10: 0.003
B11: Omega mod | E11: 0.026 | F11: 0.043 | G11: 0.02 | I11: Omega mod | L11: 0.009 | M11: 0.01 | N11: 0.02
B12: Delta mod | E12: 0.0015 | F12: 0.002 | G12: 0.0015 | I12: Delta mod | L12: 0.001 | M12: 0.002 | N12: 0.0015
B13: Emerald Egg mod | G13: 0.00475 | I13: Emerald Egg mod | N13: 0.0025
B16: Deadwood Canyon Chest Data | D16: White | E16: Cyan | F16: Yellow | G16: Green | I16: Boiling Mine Chest Data | K16: White | L16: Cyan | M16: Yellow | N16: Green
B17: o Common o | F17: 0.364 | G17: 0.97925 | I17: o Common o | K17: 0.79 | L17: 0.865 | M17: 0.85 | N17: 0.97925
B18: 8 Giant 8 | D18: 1 | E18: 0.975 | F18: 0.6 | I18: 8 Giant 8 | K18: 0.17 | L18: 0.1 | M18: 0.1
B19: Ω Omega Ω | E19: 0.02 | F19: 0.03 | G19: 0.02 | I19: Ω Omega Ω | K19: 0.035 | L19: 0.03 | M19: 0.04 | N19: 0.02
B20: Δ Delta Δ | E20: 0.005 | F20: 0.006 | G20: 0.0005 | I20: Δ Delta Δ | K20: 0.005 | L20: 0.005 | M20: 0.01 | N20: 0.0005
B21: Emerald Egg | G21: 0.00025 | I21: Emerald Egg | N21: 0.00025
B22: Common mod | F22: -0.0248 | G22: -0.0235 | I22: Common mod | L22: -0.01 | M22: -0.032 | N22: -0.02425
B23: Giant mod | E23: -0.0055 | F23: 0.015 | I23: Giant mod | L23: 0 | M23: 0
B24: Omega mod | E24: 0.005 | F24: 0.009 | G24: 0.02 | I24: Omega mod | L24: 0.009 | M24: 0.03 | N24: 0.02
B25: Delta mod | E25: 0.0005 | F25: 0.0008 | G25: 0.0015 | I25: Delta mod | L25: 0.001 | M25: 0.002 | N25: 0.0015
B26: Emerald Egg mod | G26: 0.002 | I26: Emerald Egg mod | N26: 0.00275
B29: Caves of Fear Chest Data | D29: White | E29: Cyan | F29: Yellow | G29: Green | I29: Icy Ridge Chest Data | K29: White | L29: Cyan | M29: Yellow | N29: Green
B30: o Common o | D30: 0.8525 | E30: 0.8675 | F30: 0.851 | G30: 0.97925 | I30: o Common o | K30: 0.79 | L30: 0.74 | M30: 0.72 | N30: 0.97925
B31: 8 Giant 8 | D31: 0.125 | E31: 0.11 | F31: 0.11 | I31: 8 Giant 8 | K31: 0.14 | L31: 0.2 | M31: 0.2
B32: Ω Omega Ω | D32: 0.02 | E32: 0.02 | F32: 0.035 | G32: 0.02 | I32: Ω Omega Ω | K32: 0.06 | L32: 0.05 | M32: 0.06 | N32: 0.02
B33: Δ Delta Δ | D33: 0.0025 | E33: 0.0025 | F33: 0.004 | G33: 0.0005 | I33: Δ Delta Δ | K33: 0.01 | L33: 0.01 | M33: 0.02 | N33: 0.0005
B34: Emerald Egg | G34: 0.00025 | I34: Emerald Egg | N34: 0.00025
B35: Common mod | E35: -0.0048 | F35: -0.0054 | G35: -0.0235 | I35: Common mod | L35: -0.0065 | M35: -0.0108 | N35: -0.02375
B36: Giant mod | E36: 0.002 | F36: 0 | I36: Giant mod | L36: 0 | M36: 0
B37: Omega mod | E37: 0.0025 | F37: 0.005 | G37: 0.02 | I37: Omega mod | L37: 0.006 | M37: 0.01 | N37: 0.02
B38: Delta mod | E38: 0.0003 | F38: 0.0004 | G38: 0.0015 | I38: Delta mod | L38: 0.0005 | M38: 0.0008 | N38: 0.0015
B39: Emerald Egg mod | G39: 0.002 | I39: Emerald Egg mod | N39: 0.00225
B42: Mushroom Forest Chest Data | D42: White | E42: Cyan | F42: Yellow | G42: Green | I42: Temple Chest Data | K42: White | L42: Cyan | M42: Yellow | N42: Green
B43: o Common o | D43: 0.75 | E43: 0.75 | F43: 0.717 | G43: 0.97925 | I43: o Common o | K43: 0.6 | L43: 0.6 | M43: =I120 -> 0.525 | N43: 0.97925
B44: 8 Giant 8 | D44: 0.2 | E44: 0.2 | F44: 0.2 | I44: 8 Giant 8 | K44: 0.335 | L44: 0.335 | M44: =I121 -> 0.335
B45: Ω Omega Ω | D45: 0.045 | E45: 0.045 | F45: 0.075 | G45: 0.02 | I45: Ω Omega Ω | K45: 0.05 | L45: 0.05 | M45: =I122 -> 0.12 | N45: 0.02
B46: Δ Delta Δ | D46: 0.005 | E46: 0.005 | F46: 0.008 | G46: 0.0005 | I46: Δ Delta Δ | K46: 0.015 | L46: 0.015 | M46: =I123 -> 0.02 | N46: 0.0005
B47: Emerald Egg | G47: 0.00025 | I47: Emerald Egg | N47: 0.00025
B48: Common mod | E48: -0.0086 | F48: -0.0099 | G48: -0.0235 | I48: Common mod | L48: -0.015 | M48: -0.0415 | N48: -0.0245
...
